Workbook

Sheet Cover
A1: ■ VOLKSWAGEN AG | EQUITY RESEARCH & VALUATION |
A5: VOLKSWAGEN AG
A8: Company Valuation & Financial Modeling
A10: Discounted Cash Flow · Trading Comparables · Scenario Analysis · WACC
A13: Ticker | E13: VOW3.DE (Preferred) / VOW.DE (Ordinary)
A15: Exchange | E15: Frankfurt Stock Exchange (XETRA)
A17: Headquarters | E17: Wolfsburg, Lower Saxony, Germany
A19: Currency | E19: EUR (€ million)
A21: Data Range | E21: FY2021–FY2025 Historical | FY2026E–FY2030E Forecast
A23: Data Source | E23: Volkswagen AG Annual Reports 2022–2025 + Q1 2026 Interim Report
A25: Analysis Date | E25: 46204
A27: Prepared By | E27: Shekhar Tanwar
A30: ■ MODEL STRUCTURE
A31: No. | C31: Sheet Name | F31: Description
A32: 1 | C32: Cover | F32: Professional cover page
A33: 2 | C33: Assumptions | F33: WACC inputs, growth rates, margin assumptions
A34: 3 | C34: Historical P&L | F34: Income Statement FY2021–FY2025
A35: 4 | C35: Ratio Analysis | F35: Profitability · Liquidity · Leverage · Efficiency
A36: 5 | C36: Revenue Forecast | F36: Bear / Base / Bull 3-scenario model 2026–2030
A37: 6 | C37: Projected P&L | F37: Forecasted Income Statement 2026–2030
A38: 7 | C38: FCF Build | F38: Free Cash Flow to Firm — EBIT → FCFF
A39: 8 | C39: WACC | F39: Weighted Average Cost of Capital via CAPM
A40: 9 | C40: DCF Valuation | F40: EV via DCF · Bridge · Intrinsic Price = €546.55
A41: 10 | C41: Comps | F41: 8 peer companies · Trading multiples
A42: 11 | C42: Sensitivity | F42: 2D Table: WACC × Terminal Growth Rate
A43: 12 | C43: Football Field | F43: Valuation range chart — all methods
A44: 13 | C44: KPI Dashboard | F44: Executive summary · Charts · Verdict
A47: ★ VALUATION RESULT
A48: INTRINSIC PRICE | G48: ='DCF Valuation'!B38 -> 546.5539
A51: VERDICT | G51: ='DCF Valuation'!B45 -> UNDERVALUED ▲
A52: Current Market Price: €86.40 | Upside: +532.6% | Method: DCF Base Case
A54: DISCLAIMER: This model is prepared solely for educational/MBA purposes. Not investment advice.

Sheet Assumptions
A1: VOLKSWAGEN AG — MODEL ASSUMPTIONS
A2: All inputs highlighted in BLUE are hardcoded assumptions. Black cells are formulas. Green cells link from other sheets.
A4: A. REVENUE GROWTH ASSUMPTIONS
A5: Scenario / Item | B5: 2026E | C5: 2027E | D5: 2028E | E5: 2029E | F5: 2030E
A6: Base Case — Revenue Growth (%) | B6: =[1]Assumptions!C8 -> 0.03 | C6: =[1]Assumptions!D8 -> 0.035 | D6: =[1]Assumptions!E8 -> 0.03 | E6: =[1]Assumptions!F8 -> 0.025 | F6: =[1]Assumptions!G8 -> 0
A7: Bull Case — Revenue Growth (%) | B7: 0.05 | C7: 0.06 | D7: 0.06 | E7: 0.05 | F7: 0.05
A8: Base Case — Revenue Growth (%) | B8: 0.025 | C8: 0.03 | D8: 0.035 | E8: 0.03 | F8: 0.025
A9: Bear Case — Revenue Growth (%) | B9: 0 | C9: -0.01 | D9: -0.01 | E9: 0.01 | F9: 0.02
A11: B. MARGIN ASSUMPTIONS (% of Revenue)
A12: Margin Item | B12: 2026E | C12: 2027E | D12: 2028E | E12: 2029E | F12: 2030E
A13: COGS % of Revenue | B13: 0.84 | C13: 0.835 | D13: 0.83 | E13: 0.828 | F13: 0.825
A14: Gross Margin % | B14: =1-B13 -> 0.16 | C14: =1-C13 -> 0.165 | D14: =1-D13 -> 0.17 | E14: =1-E13 -> 0.172 | F14: =1-F13 -> 0.175
A15: Distribution Exp % Revenue | B15: 0.071 | C15: 0.07 | D15: 0.069 | E15: 0.068 | F15: 0.068
A16: Admin Exp % Revenue | B16: 0.039 | C16: 0.038 | D16: 0.038 | E16: 0.037 | F16: 0.037
A17: Other Operating Net % Rev | B17: -0.02 | C17: -0.018 | D17: -0.016 | E17: -0.015 | F17: -0.014
A18: EBIT Margin (Implied) | B18: =1-B13-B15-B16+B17 -> 0.03 | C18: =1-C13-C15-C16+C17 -> 0.039 | D18: =1-D13-D15-D16+D17 -> 0.047 | E18: =1-E13-E15-E16+E17 -> 0.052 | F18: =1-F13-F15-F16+F17 -> 0.056
A19: Effective Tax Rate | B19: 0.28 | C19: 0.28 | D19: 0.28 | E19: 0.28 | F19: 0.28
A21: C. CAPEX & DEPRECIATION ASSUMPTIONS
A22: Item | B22: 2026E | C22: 2027E | D22: 2028E | E22: 2029E | F22: 2030E
A23: CapEx % Revenue (PPE+Intangibles) | B23: 0.048 | C23: 0.047 | D23: 0.046 | E23: 0.045 | F23: 0.044
A24: Capitalized Dev Costs % Revenue | B24: 0.028 | C24: 0.027 | D24: 0.026 | E24: 0.025 | F24: 0.024
A25: D&A PPE % Revenue | B25: 0.04 | C25: 0.04 | D25: 0.039 | E25: 0.039 | F25: 0.038
A26: D&A Dev Costs % Revenue | B26: 0.024 | C26: 0.024 | D26: 0.023 | E26: 0.023 | F26: 0.022
A27: Total D&A % Revenue (approx.) | B27: =B25+B26 -> 0.064 | C27: =C25+C26 -> 0.064 | D27: =D25+D26 -> 0.062 | E27: =E25+E26 -> 0.062 | F27: =F25+F26 -> 0.06
A29: D. WORKING CAPITAL ASSUMPTIONS
A30: Item | B30: 2026E | C30: 2027E | D30: 2028E | E30: 2029E | F30: 2030E
A31: Days Inventory Outstanding (DIO) | B31: 62 | C31: 61 | D31: 60 | E31: 60 | F31: 59
A32: Days Sales Outstanding (DSO) | B32: 21 | C32: 21 | D32: 20 | E32: 20 | F32: 20
A33: Days Payable Outstanding (DPO) | B33: 39 | C33: 39 | D33: 40 | E33: 40 | F33: 41
A34: Cash Conversion Cycle (days) | B34: =B31+B32-B33 -> 44 | C34: =C31+C32-C33 -> 43 | D34: =D31+D32-D33 -> 40 | E34: =E31+E32-E33 -> 40 | F34: =F31+F32-F33 -> 38
A36: E. WACC INPUTS
A37: Parameter | B37: Value | C37: Notes
A38: Risk-Free Rate (German 10Y Bund Yield) | B38: 0.028 | C38: 0.028
A39: Equity Risk Premium (ERP — Damodaran EU) | B39: 0.055 | C39: 0.055
A40: VW Beta (5Y Monthly vs DAX, Adjusted) | B40: 1.1 | C40: 1.1
A41: Cost of Equity (CAPM = Rf + β × ERP) | B41: =C38+C39*C40 -> 0.0885 | C41: =C38+C39*C40 -> 0.0885
A42: Pre-Tax Cost of Debt | B42: 0.045 | C42: VW bond yield, weighted avg maturity
A43: Effective Tax Rate (for Kd) | B43: 0.28 | C43: 0.045
A44: After-Tax Cost of Debt | B44: =C43*(1-C44) -> 0.0324 | C44: 0.28
A45: Market Value of Equity (€B, approx.) | B45: 42 | C45: =C43*(1-C44) -> 0.0324
...

Sheet Historical P&L
A3: Line Item (€ million) | B3: 2021 | C3: 2022 | D3: 2023 | E3: 2024 | F3: 2025
A4: A. TOP LINE
A5: Sales Revenue | B5: 250200 | C5: 279232 | D5: 322284 | E5: 324656 | F5: 321913
A6: YoY Growth (%) | C6: =(C5-B5)/B5 -> 0.11603517 | D6: =(D5-C5)/C5 -> 0.15418004 | E6: =(E5-D5)/D5 -> 0.0073599682 | F6: =(F5-E5)/E5 -> -0.0084489429
A8: B. COST STRUCTURE
A9: Cost of Sales | B9: -202959 | C9: -227005 | D9: -261262 | E9: -265184 | F9: -270671
A10: Gross Result | B10: =B5+B9 -> 47241 | C10: =C5+C9 -> 52227 | D10: =D5+D9 -> 61022 | E10: =E5+E9 -> 59472 | F10: =F5+F9 -> 51242
A11: Gross Margin % | B11: =B10/B5 -> 0.18881295 | C11: =C10/C5 -> 0.18703802 | D11: =D10/D5 -> 0.18934232 | E11: =E10/E5 -> 0.18318466 | F11: =F10/F5 -> 0.15917965
A12: Distribution Exp | B12: -19228 | C12: -19840 | D12: -21340 | E12: -22320 | F12: -22804
A13: Admin Expenses | B13: -10420 | C13: -11689 | D13: -12724 | E13: -12754 | F13: -12541
A14: Other Operating Income/Expense (Net) | B14: 1682 | C14: 1421 | D14: -4382 | E14: -5338 | F14: -7029
A16: C. OPERATING RESULT
A17: EBIT | B17: =B10+B12+B13+B14 -> 19275 | C17: =C10+C12+C13+C14 -> 22119 | D17: =D10+D12+D13+D14 -> 22576 | E17: =E10+E12+E13+E14 -> 19060 | F17: =F10+F12+F13+F14 -> 8868
A18: EBIT Margin % | B18: =B17/B5 -> 0.077038369 | C18: =C17/C5 -> 0.0792137 | D18: =D17/D5 -> 0.070050018 | E18: =E17/E5 -> 0.058708294 | F18: =F17/F5 -> 0.027547816
A20: D. BELOW THE LINE
A21: Share of Result — Equity Investments | B21: 2403 | C21: 2403 | D21: 2291 | E21: 375 | F21: 930
A22: Interest Income | B22: 651 | C22: 1325 | D22: 2658 | E22: 2419 | F22: 1824
A23: Interest Expense | B23: -408 | C23: -408 | D23: -3592 | E23: -3446 | F23: -3245
A24: Other Financial Result | B24: -526 | C24: -1301 | D24: -739 | E24: -1602 | F24: 930
A25: Financial Result | B25: =B21+B22+B23+B24 -> 2120 | C25: =C21+C22+C23+C24 -> 2019 | D25: =D21+D22+D23+D24 -> 618 | E25: =E21+E22+E23+E24 -> -2254 | F25: =F21+F22+F23+F24 -> 439
A27: E. EARNINGS
A28: Earnings Before Tax (EBT) | B28: 20126 | C28: 22044 | D28: 23194 | E28: 16806 | F28: 9307
A29: Income Tax Expense | B29: -4698 | C29: -6208 | D29: -5237 | E29: -4411 | F29: -2403
A30: Effective Tax Rate % | B30: =B29/B28 -> -0.23342939 | C30: =C29/C28 -> -0.28161858 | D30: =D29/D28 -> -0.22579115 | E30: =E29/E28 -> -0.26246579 | F30: =F29/F28 -> -0.25819276
A31: Earnings After Tax | B31: =B28+B29 -> 15428 | C31: =C28+C29 -> 15836 | D31: =D28+D29 -> 17957 | E31: =E28+E29 -> 12395 | F31: =F28+F29 -> 6904
A32: Non-Controlling Interests | B32: -624 | C32: -1043 | D32: -1329 | E32: -1043 | F32: 419
A33: Hybrid Capital Investors (Coupon) | B33: -486 | C33: -630 | D33: -586 | E33: -630 | F33: -650
A34: Net Income to VW AG Shareholders | B34: =B31+B32+B33 -> 14318 | C34: =C31+C32+C33 -> 14163 | D34: =D31+D32+D33 -> 16042 | E34: =E31+E32+E33 -> 10722 | F34: =F31+F32+F33 -> 6673
A35: Net Margin % | B35: =B34/B5 -> 0.057226219 | C35: =C34/C5 -> 0.050721264 | D35: =D34/D5 -> 0.049775974 | E35: =E34/E5 -> 0.033025726 | F35: =F34/F5 -> 0.020729203
A37: F. PER SHARE DATA
A38: EPS — Ordinary Share (€) | B38: 29.59 | C38: 29.63 | D38: 31.79 | E38: 21.36 | F38: 13.29
A39: EPS — Preferred Share (€) | B39: 29.65 | C39: 29.69 | D39: 31.85 | E39: 21.42 | F39: 13.35
A40: Shares Outstanding — Ordinary (million) | B40: 295.09 | C40: 295.09 | D40: 295.09 | E40: 295.09 | F40: 295.09
A41: Shares Outstanding — Preferred (million) | B41: 206.21 | C41: 206.21 | D41: 206.21 | E41: 206.21 | F41: 206.21
A42: Total Shares Outstanding (million) | B42: 501.3 | C42: 501.3 | D42: 501.3 | E42: 501.3 | F42: 501.3

Sheet Ratio Analysis
A1: VOLKSWAGEN AG — FINANCIAL RATIO ANALYSIS
A2: All ratios calculated from Historical P&L and Balance Sheet. Formulas auto-linked.
A4: RATIO | B4: 2021 | C4: 2022 | D4: 2023 | E4: 2024 | F4: 2025 | G4: Benchmark
A5: ★ BALANCE SHEET KEY DATA (€ million) — for ratio calculation
A6: Item | B6: 2021 | C6: 2022 | D6: 2023 | E6: 2024 | F6: 2025 | G6: Source
A7: Total Assets | B7: 528609 | C7: 564772 | D7: 600338 | E7: 632905 | F7: 644467
A8: Total Equity | B8: 146154 | C8: 178327 | D8: 189912 | E8: 196731 | F8: 203054
A9: Cash & Equivalents | B9: 39723 | C9: 29172 | D9: 43522 | E9: 40296 | F9: 38801
A10: Inventories | B10: 43725 | C10: 52274 | D10: 56042 | E10: 60048 | F10: 56042
A11: Current Assets | B11: 200347 | C11: 224309 | D11: 236413 | E11: 257221 | F11: 247865
A12: Current Liabilities | B12: 205456 | C12: 205620 | D12: 205874 | E12: 225498 | F12: 226525
A13: Total Debt (Gross) | B13: 210202 | C13: 205185 | D13: 232799 | E13: 261541 | F13: 264703
A14: Trade Payables | B14: 23624 | C14: 28748 | D14: 30578 | E14: 30490 | F14: 30490
A15: Trade Receivables | B15: 15521 | C15: 18581 | D15: 21134 | E15: 20760 | F15: 20760
A16: Net Debt (Gross Debt − Cash) | B16: =B13-B9 -> 170479 | C16: =C13-C9 -> 176013 | D16: =D13-D9 -> 189277 | E16: =E13-E9 -> 221245 | F16: =F13-F9 -> 225902
A17: EBIT | B17: ='Historical P&L'!B17 -> 19275 | C17: ='Historical P&L'!C17 -> 22119 | D17: ='Historical P&L'!D17 -> 22576 | E17: ='Historical P&L'!E17 -> 19060 | F17: ='Historical P&L'!F17 -> 8868
A18: Net Income VW Shareholders | B18: ='Historical P&L'!B34 -> 14318 | C18: ='Historical P&L'!C34 -> 14163 | D18: ='Historical P&L'!D34 -> 16042 | E18: ='Historical P&L'!E34 -> 10722 | F18: ='Historical P&L'!F34 -> 6673
A19: Revenue | B19: ='Historical P&L'!B5 -> 250200 | C19: ='Historical P&L'!C5 -> 279232 | D19: ='Historical P&L'!D5 -> 322284 | E19: ='Historical P&L'!E5 -> 324656 | F19: ='Historical P&L'!F5 -> 321913
A21: A. PROFITABILITY RATIOS
A22: Ratio | B22: 2021 | C22: 2022 | D22: 2023 | E22: 2024 | F22: 2025 | G22: Industry Avg
A23: Gross Margin % | B23: ='Historical P&L'!B11 -> 0.18881295 | C23: ='Historical P&L'!C11 -> 0.18703802 | D23: ='Historical P&L'!D11 -> 0.18934232 | E23: ='Historical P&L'!E11 -> 0.18318466 | F23: ='Historical P&L'!F11 -> 0.15917965 | G23: 18–22%
A24: EBIT Margin % | B24: ='Historical P&L'!B18 -> 0.077038369 | C24: ='Historical P&L'!C18 -> 0.0792137 | D24: ='Historical P&L'!D18 -> 0.070050018 | E24: ='Historical P&L'!E18 -> 0.058708294 | F24: ='Historical P&L'!F18 -> 0.027547816 | G24: 5–8%
A25: Net Profit Margin % | B25: =B18/B19 -> 0.057226219 | C25: =C18/C19 -> 0.050721264 | D25: =D18/D19 -> 0.049775974 | E25: =E18/E19 -> 0.033025726 | F25: =F18/F19 -> 0.020729203 | G25: 3–5%
A26: Return on Assets (ROA %) | B26: =B18/B7 -> 0.027086183 | C26: =C18/C7 -> 0.025077376 | D26: =D18/D7 -> 0.026721613 | E26: =E18/E7 -> 0.016940931 | F26: =F18/F7 -> 0.010354293 | G26: 2–4%
A27: Return on Equity (ROE %) | B27: =B18/B8 -> 0.09796516 | C27: =C18/C8 -> 0.079421512 | D27: =D18/D8 -> 0.084470702 | E27: =E18/E8 -> 0.054500816 | F27: =F18/F8 -> 0.032863179 | G27: 8–12%
A28: EBITDA Margin % (approx.) | B28: =B29/B19 -> 0.12858513 | C28: =C29/C19 -> 0.14551341 | D28: =D29/D19 -> 0.12252237 | E28: =E29/E19 -> 0.12113437 | F28: =F29/F19 -> 0.10592614
A29: EBITDA (€M) | B29: 32172 | C29: 40632 | D29: 39487 | E29: 39327 | F29: 34099
A31: B. LIQUIDITY RATIOS
A32: Ratio | B32: 2021 | C32: 2022 | D32: 2023 | E32: 2024 | F32: 2025 | G32: Industry Avg
A33: Current Ratio | B33: =B11/B12 -> 0.97513336 | C33: =C11/C12 -> 1.090891 | D33: =D11/D12 -> 1.1483383 | E33: =E11/E12 -> 1.1406797 | F33: =F11/F12 -> 1.0942059 | G33: 0.9-1.2x
A34: Quick Ratio | B34: =(B11-B10)/B12 -> 0.76231407 | C34: =(C11-C10)/C12 -> 0.83666472 | D34: =(D11-D10)/D12 -> 0.87612326 | E34: =(E11-E10)/E12 -> 0.87438913 | F34: =(F11-F10)/F12 -> 0.8468072 | G34: 0.6-0.9x
A35: Cash Ratio | B35: =B9/B12 -> 0.19334067 | C35: =C9/C12 -> 0.14187336 | D35: =D9/D12 -> 0.21140115 | E35: =E9/E12 -> 0.17869782 | F35: =F9/F12 -> 0.17128794 | G35: 0.1-0.3x
A37: C. LEVERAGE RATIOS
A38: Ratio | B38: 2021 | C38: 2022 | D38: 2023 | E38: 2024 | F38: 2025 | G38: Benchmark
A39: Gross Debt/Equity | B39: =B13/B8 -> 1.4382227 | C39: =C13/C8 -> 1.150611 | D39: =D13/D8 -> 1.2258256 | E39: =E13/E8 -> 1.3294346 | F39: =F13/F8 -> 1.3036089 | G39: 0.3–0.8x
A40: Net Debt/Equity | B40: =B16/B8 -> 1.166434 | C40: =C16/C8 -> 0.98702384 | D40: =D16/D8 -> 0.99665635 | E40: =E16/E8 -> 1.1246067 | F40: =F16/F8 -> 1.1125218 | G40: Excl. Fin. Svcs
A41: Net Debt/EBITDA | B41: =B16/B29 -> 5.2989867 | C41: =C16/C29 -> 4.3318813 | D41: =D16/D29 -> 4.7934004 | E41: =E16/E29 -> 5.6257787 | F41: =F16/F29 -> 6.6248864 | G41: 1.0–2.0x
A42: Debt/Total Assets | B42: =B13/B7 -> 0.39765119 | C42: =C13/C7 -> 0.3633059 | D42: =D13/D7 -> 0.38777988 | E42: =E13/E7 -> 0.41323895 | F42: =F13/F7 -> 0.41073166 | G42: <0.7x
A43: Interest Coverage | B43: =B17/B44 -> 47.242647 | C43: =C17/C44 -> 54.213235 | D43: =D17/D44 -> 6.285078 | E43: =E17/E44 -> 5.5310505 | F43: =F17/F44 -> 2.7328197 | G43: >3.0x
A44: Interest Expense (helper row — hidden) | B44: 408 | C44: 408 | D44: 3592 | E44: 3446 | F44: 3245
...

Sheet Revenue Forecast
A1: VOLKSWAGEN AG — REVENUE FORECAST (€ million) | BEAR / BASE / BULL
A2: Growth rates linked from Assumptions sheet. FY2025 Actual = base year. All forecasts 2026E–2030E.
A4: SCENARIO / ITEM | B4: 2025A | C4: 2026E | D4: 2027E | E4: 2028E | F4: 2029E | G4: 2030E | H4: CAGR 25-30
A5: ★ BASE CASE — Revenue Projection
A6: Revenue Growth Rate (%) | C6: =Assumptions!B8 -> 0.025 | D6: =Assumptions!C8 -> 0.03 | E6: =Assumptions!D8 -> 0.035 | F6: =Assumptions!E8 -> 0.03 | G6: =Assumptions!F8 -> 0.025
A7: Sales Revenue — Base Case (€M) | B7: 321913 | C7: =B7*(1+C6) -> 329960.82 | D7: =C7*(1+D6) -> 339859.65 | E7: =D7*(1+E6) -> 351754.74 | F7: =E7*(1+F6) -> 362307.38 | G7: =F7*(1+G6) -> 371365.06 | H7: =(G7/B7)^(1/5)-1 -> 0.028993203
A9: ▲ BULL CASE — Optimistic Projection
A10: Revenue Growth Rate (%) | C10: =Assumptions!B7 -> 0.05 | D10: =Assumptions!C7 -> 0.06 | E10: =Assumptions!D7 -> 0.06 | F10: =Assumptions!E7 -> 0.05 | G10: =Assumptions!F7 -> 0.05
A11: Sales Revenue — Bull Case (€M) | B11: 321913 | C11: =B11*(1+C10) -> 338008.65 | D11: =C11*(1+D10) -> 358289.17 | E11: =D11*(1+E10) -> 379786.52 | F11: =E11*(1+F10) -> 398775.85 | G11: =F11*(1+G10) -> 418714.64 | H11: =(G11/B11)^(1/5)-1 -> 0.053988629
A13: ▼ BEAR CASE — Conservative Projection
A14: Revenue Growth Rate (%) | C14: =Assumptions!B9 -> 0 | D14: =Assumptions!C9 -> -0.01 | E14: =Assumptions!D9 -> -0.01 | F14: =Assumptions!E9 -> 0.01 | G14: =Assumptions!F9 -> 0.02
A15: Sales Revenue — Bear Case (€M) | B15: 321913 | C15: =B15*(1+C14) -> 321913 | D15: =C15*(1+D14) -> 318693.87 | E15: =D15*(1+E14) -> 315506.93 | F15: =E15*(1+F14) -> 318662 | G15: =F15*(1+G14) -> 325035.24 | H15: =(G15/B15)^(1/5)-1 -> 0.0019323218
A17: SCENARIO COMPARISON SUMMARY
A18: Scenario | B18: 2025A | C18: 2026E | D18: 2027E | E18: 2028E | F18: 2029E | G18: 2030E | H18: 5Y CAGR
A19: Base Case | B19: =B7 -> 321913 | C19: =C7 -> 329960.82 | D19: =D7 -> 339859.65 | E19: =E7 -> 351754.74 | F19: =F7 -> 362307.38 | G19: =G7 -> 371365.06 | H19: =H7 -> 0.028993203
A20: Bull Case | B20: =B11 -> 321913 | C20: =C11 -> 338008.65 | D20: =D11 -> 358289.17 | E20: =E11 -> 379786.52 | F20: =F11 -> 398775.85 | G20: =G11 -> 418714.64 | H20: =H11 -> 0.053988629
A21: Bear Case | B21: =B15 -> 321913 | C21: =C15 -> 321913 | D21: =D15 -> 318693.87 | E21: =E15 -> 315506.93 | F21: =F15 -> 318662 | G21: =G15 -> 325035.24 | H21: =H15 -> 0.0019323218

Sheet Projected P&L
A1: VOLKSWAGEN AG — PROJECTED INCOME STATEMENT (€ million) | BASE CASE
A2: Revenue from Revenue Forecast sheet (Base Case). All margins from Assumptions sheet. Formulas fully linked.
A4: LINE ITEM (€ million) | B4: 2025A | C4: 2026E | D4: 2027E | E4: 2028E | F4: 2029E | G4: 2030E
A5: A. TOP LINE
A6: Sales Revenue | B6: ='Historical P&L'!F5 -> 321913 | C6: ='Revenue Forecast'!C7 -> 329960.82 | D6: ='Revenue Forecast'!D7 -> 339859.65 | E6: ='Revenue Forecast'!E7 -> 351754.74 | F6: ='Revenue Forecast'!F7 -> 362307.38 | G6: ='Revenue Forecast'!G7 -> 371365.06
A7: YoY Growth (%) | C7: =(C6-B6)/B6 -> 0.025 | D7: =(D6-C6)/C6 -> 0.03 | E7: =(E6-D6)/D6 -> 0.035 | F7: =(F6-E6)/E6 -> 0.03 | G7: =(G6-F6)/F6 -> 0.025
A9: B. COST STRUCTURE
A10: Cost of Sales | B10: ='Historical P&L'!F9 -> -270671 | C10: =-Assumptions!B13*C6 -> -277167.09 | D10: =-Assumptions!C13*D6 -> -283782.81 | E10: =-Assumptions!D13*E6 -> -291956.43 | F10: =-Assumptions!E13*F6 -> -299990.51 | G10: =-Assumptions!F13*G6 -> -306376.18
A11: Gross Result | B11: =B6+B10 -> 51242 | C11: =C6+C10 -> 52793.732 | D11: =D6+D10 -> 56076.842 | E11: =E6+E10 -> 59798.305 | F11: =F6+F10 -> 62316.869 | G11: =G6+G10 -> 64988.886
A12: Gross Margin % | B12: =B11/B6 -> 0.15917965 | C12: =C11/C6 -> 0.16 | D12: =D11/D6 -> 0.165 | E12: =E11/E6 -> 0.17 | F12: =F11/F6 -> 0.172 | G12: =G11/G6 -> 0.175
A13: Distribution Expenses | B13: ='Historical P&L'!F12 -> -22804 | C13: =-Assumptions!B15*C6 -> -23427.219 | D13: =-Assumptions!C15*D6 -> -23790.175 | E13: =-Assumptions!D15*E6 -> -24271.077 | F13: =-Assumptions!E15*F6 -> -24636.902 | G13: =-Assumptions!F15*G6 -> -25252.824
A14: Administrative Expenses | B14: ='Historical P&L'!F13 -> -12541 | C14: =-Assumptions!B16*C6 -> -12868.472 | D14: =-Assumptions!C16*D6 -> -12914.667 | E14: =-Assumptions!D16*E6 -> -13366.68 | F14: =-Assumptions!E16*F6 -> -13405.373 | G14: =-Assumptions!F16*G6 -> -13740.507
A15: Other Operating Income/Exp (Net) | B15: ='Historical P&L'!F14 -> -7029 | C15: =Assumptions!B17*C6 -> -6599.2165 | D15: =Assumptions!C17*D6 -> -6117.4737 | E15: =Assumptions!D17*E6 -> -5628.0758 | F15: =Assumptions!E17*F6 -> -5434.6107 | G15: =Assumptions!F17*G6 -> -5199.1109
A17: C. OPERATING RESULT (EBIT)
A18: Operating Result (EBIT) | B18: =B11+B13+B14+B15 -> 8868 | C18: =C11+C13+C14+C15 -> 9898.8248 | D18: =D11+D13+D14+D15 -> 13254.526 | E18: =E11+E13+E14+E15 -> 16532.473 | F18: =F11+F13+F14+F15 -> 18839.984 | G18: =G11+G13+G14+G15 -> 20796.444
A19: EBIT Margin % | B19: =B18/B6 -> 0.027547816 | C19: =C18/C6 -> 0.03 | D19: =D18/D6 -> 0.039 | E19: =E18/E6 -> 0.047 | F19: =F18/F6 -> 0.052 | G19: =G18/G6 -> 0.056
A21: D. BELOW EBIT — EARNINGS
A22: Financial Result (est.) | B22: ='Historical P&L'!F25 -> 439 | C22: -1500 | D22: -1500 | E22: -1200 | F22: -1200 | G22: -1000
A23: Earnings Before Tax (EBT) | B23: =B18+B22 -> 9307 | C23: =C18+C22 -> 8398.8248 | D23: =D18+D22 -> 11754.526 | E23: =E18+E22 -> 15332.473 | F23: =F18+F22 -> 17639.984 | G23: =G18+G22 -> 19796.444
A24: Income Tax Expense | B24: ='Historical P&L'!F29 -> -2403 | C24: =-Assumptions!B19*C23 -> -2351.6709 | D24: =-Assumptions!C19*D23 -> -3291.2674 | E24: =-Assumptions!D19*E23 -> -4293.0923 | F24: =-Assumptions!E19*F23 -> -4939.1954 | G24: =-Assumptions!F19*G23 -> -5543.0042
A25: Earnings After Tax | B25: =B23+B24 -> 6904 | C25: =C23+C24 -> 6047.1538 | D25: =D23+D24 -> 8463.259 | E25: =E23+E24 -> 11039.38 | F25: =F23+F24 -> 12700.788 | G25: =G23+G24 -> 14253.439
A26: Non-Controlling Interests | B26: ='Historical P&L'!F32 -> 419 | C26: -500 | D26: -500 | E26: -500 | F26: -500 | G26: -500
A27: Hybrid Capital Investors (Coupon) | B27: ='Historical P&L'!F33 -> -650 | C27: -650 | D27: -650 | E27: -650 | F27: -650 | G27: -650
A28: Net Income — VW AG Shareholders | B28: =B25+B26+B27 -> 6673 | C28: =C25+C26+C27 -> 4897.1538 | D28: =D25+D26+D27 -> 7313.259 | E28: =E25+E26+E27 -> 9889.3803 | F28: =F25+F26+F27 -> 11550.788 | G28: =G25+G26+G27 -> 13103.439
A29: Net Margin % | B29: =B28/B6 -> 0.020729203 | C29: =C28/C6 -> 0.014841622 | D29: =D28/D6 -> 0.021518468 | E29: =E28/E6 -> 0.02811442 | F29: =F28/F6 -> 0.031881184 | G29: =G28/G6 -> 0.035284524
A31: E. PER SHARE DATA
A32: EPS — Preferred Share (€) | B32: ='Historical P&L'!F38 -> 13.29 | C32: =C28/501.3 -> 9.7689085 | D32: =D28/501.3 -> 14.588588 | E32: =E28/501.3 -> 19.727469 | F32: =F28/501.3 -> 23.041668 | G32: =G28/501.3 -> 26.138918

Sheet FCF Build
A1: VOLKSWAGEN AG — FREE CASH FLOW TO FIRM (FCFF) (€ million)
A2: FCFF = EBIT×(1−t) + D&A − CapEx − ΔWorking Capital | Base Case
A4: FCF BUILD (€ million) | B4: 2025A | C4: 2026E | D4: 2027E | E4: 2028E | F4: 2029E | G4: 2030E
A5: STEP 1 — EBIT & NOPAT (Net Operating Profit After Tax)
A6: Operating Result (EBIT) | B6: ='Historical P&L'!F17 -> 8868 | C6: ='Projected P&L'!C18 -> 9898.8248 | D6: ='Projected P&L'!D18 -> 13254.526 | E6: ='Projected P&L'!E18 -> 16532.473 | F6: ='Projected P&L'!F18 -> 18839.984 | G6: ='Projected P&L'!G18 -> 20796.444
A7: Effective Tax Rate | B7: =ABS('Historical P&L'!F30) -> 0.25819276 | C7: =Assumptions!B19 -> 0.28 | D7: =Assumptions!C19 -> 0.28 | E7: =Assumptions!D19 -> 0.28 | F7: =Assumptions!E19 -> 0.28 | G7: =Assumptions!F19 -> 0.28
A8: Tax on EBIT (= EBIT × Tax Rate) | B8: =-B6*B7 -> -2289.6534 | C8: =-C6*C7 -> -2771.6709 | D8: =-D6*D7 -> -3711.2674 | E8: =-E6*E7 -> -4629.0923 | F8: =-F6*F7 -> -5275.1954 | G8: =-G6*G7 -> -5823.0042
A9: NOPAT = EBIT × (1 − Tax Rate) | B9: =B6+B8 -> 6578.3466 | C9: =C6+C8 -> 7127.1538 | D9: =D6+D8 -> 9543.259 | E9: =E6+E8 -> 11903.38 | F9: =F6+F8 -> 13564.788 | G9: =G6+G8 -> 14973.439
A11: STEP 2 — ADD BACK: DEPRECIATION & AMORTIZATION
A12: + D&A — PPE & Intangibles | B12: 16866 | C12: =Assumptions!B25*'Projected P&L'!C6 -> 13198.433 | D12: =Assumptions!C25*'Projected P&L'!D6 -> 13594.386 | E12: =Assumptions!D25*'Projected P&L'!E6 -> 13718.435 | F12: =Assumptions!E25*'Projected P&L'!F6 -> 14129.988 | G12: =Assumptions!F25*'Projected P&L'!G6 -> 14111.872
A13: + Amortization — Capitalized Dev. Costs | B13: 8365 | C13: =Assumptions!B26*'Projected P&L'!C6 -> 7919.0598 | D13: =Assumptions!C26*'Projected P&L'!D6 -> 8156.6316 | E13: =Assumptions!D26*'Projected P&L'!E6 -> 8090.359 | F13: =Assumptions!E26*'Projected P&L'!F6 -> 8333.0697 | G13: =Assumptions!F26*'Projected P&L'!G6 -> 8170.0314
A14: Total D&A Add-back | B14: =B12+B13 -> 25231 | C14: =C12+C13 -> 21117.493 | D14: =D12+D13 -> 21751.018 | E14: =E12+E13 -> 21808.794 | F14: =F12+F13 -> 22463.058 | G14: =G12+G13 -> 22281.904
A16: STEP 3 — LESS: CAPITAL EXPENDITURE
A17: − CapEx (PPE + Investment Property) | B17: -15299 | C17: =-Assumptions!B23*'Projected P&L'!C6 -> -15838.12 | D17: =-Assumptions!C23*'Projected P&L'!D6 -> -15973.404 | E17: =-Assumptions!D23*'Projected P&L'!E6 -> -16180.718 | F17: =-Assumptions!E23*'Projected P&L'!F6 -> -16303.832 | G17: =-Assumptions!F23*'Projected P&L'!G6 -> -16340.063
A18: − Capitalized Development Costs | B18: -9047 | C18: =-Assumptions!B24*'Projected P&L'!C6 -> -9238.9031 | D18: =-Assumptions!C24*'Projected P&L'!D6 -> -9176.2105 | E18: =-Assumptions!D24*'Projected P&L'!E6 -> -9145.6232 | F18: =-Assumptions!E24*'Projected P&L'!F6 -> -9057.6845 | G18: =-Assumptions!F24*'Projected P&L'!G6 -> -8912.7615
A19: Total CapEx (Net Investment) | B19: =B17+B18 -> -24346 | C19: =C17+C18 -> -25077.023 | D19: =D17+D18 -> -25149.614 | E19: =E17+E18 -> -25326.341 | F19: =F17+F18 -> -25361.517 | G19: =G17+G18 -> -25252.824
A21: STEP 4 — CHANGE IN NET WORKING CAPITAL (ΔWC)
A22: − Change in Net Working Capital | B22: 896 | C22: =('Projected P&L'!C6-'Projected P&L'!B6)*0.015 -> 120.71737 | D22: =('Projected P&L'!D6-'Projected P&L'!C6)*0.015 -> 148.48237 | E22: =('Projected P&L'!E6-'Projected P&L'!D6)*0.015 -> 178.42632 | F22: =('Projected P&L'!F6-'Projected P&L'!E6)*0.015 -> 158.28963 | G22: =('Projected P&L'!G6-'Projected P&L'!F6)*0.015 -> 135.86527
A24: RESULT — FREE CASH FLOW TO FIRM (FCFF)
A26: ★ FCFF — Free Cash Flow to Firm | B26: =B9+B14+B19-B22 -> 6567.3466 | C26: =C9+C14+C19-C22 -> 3046.9065 | D26: =D9+D14+D19-D22 -> 5996.1801 | E26: =E9+E14+E19-E22 -> 8207.4066 | F26: =F9+F14+F19-F22 -> 10508.04 | G26: =G9+G14+G19-G22 -> 11866.654
A28: FCFF BUILD SUMMARY — STEP BY STEP
A29: Component | B29: 2025A | C29: 2026E | D29: 2027E | E29: 2028E | F29: 2029E | G29: 2030E
A30: NOPAT | B30: =B9 -> 6578.3466 | C30: =C9 -> 7127.1538 | D30: =D9 -> 9543.259 | E30: =E9 -> 11903.38 | F30: =F9 -> 13564.788 | G30: =G9 -> 14973.439
A31: + Total D&A | B31: =B14 -> 25231 | C31: =C14 -> 21117.493 | D31: =D14 -> 21751.018 | E31: =E14 -> 21808.794 | F31: =F14 -> 22463.058 | G31: =G14 -> 22281.904
A32: − Total CapEx | B32: =B19 -> -24346 | C32: =C19 -> -25077.023 | D32: =D19 -> -25149.614 | E32: =E19 -> -25326.341 | F32: =F19 -> -25361.517 | G32: =G19 -> -25252.824
A33: − ΔWorking Capital | B33: =-B22 -> -896 | C33: =-C22 -> -120.71737 | D33: =-D22 -> -148.48237 | E33: =-E22 -> -178.42632 | F33: =-F22 -> -158.28963 | G33: =-G22 -> -135.86527
A35: FCFF | B35: =B26 -> 6567.3466 | C35: =C26 -> 3046.9065 | D35: =D26 -> 5996.1801 | E35: =E26 -> 8207.4066 | F35: =F26 -> 10508.04 | G35: =G26 -> 11866.654

Sheet WACC
A1: VOLKSWAGEN AG — WACC CALCULATION
A2: WACC = We×Ke + Wd×Kd×(1−t) | Cost of Equity via CAPM: Ke = Rf + β×ERP
A4: PARAMETER | B4: VALUE | C4: NOTES / SOURCE
A5: A. RISK-FREE RATE
A6: German 10-Year Bund Yield (Rf) | B6: =Assumptions!B38 -> 0.028 | C6: Source: ECB / Bloomberg, June 2026
A8: B. COST OF EQUITY (Ke) — CAPM METHOD
A9: Risk-Free Rate (Rf) | B9: =B6 -> 0.028 | C9: Linked from Section A above
A10: Equity Risk Premium (ERP) | B10: =Assumptions!B39 -> 0.055 | C10: Damodaran Western Europe ERP estimate, 2026
A11: VW Beta (5Y Monthly vs DAX, Adjusted) | B11: =Assumptions!B40 -> 1.1 | C11: Bloomberg adjusted beta — between raw & 1.0
A12: Cost of Equity Ke = Rf + β × ERP | B12: =B9+B11*B10 -> 0.0885 | C12: CAPM Formula: Rf + Beta × ERP
A14: C. COST OF DEBT (Kd)
A15: Pre-Tax Cost of Debt (Kd) | B15: =Assumptions!B42 -> 0.045 | C15: VW bond yield, weighted avg maturity
A16: Effective Tax Rate (for Kd shield) | B16: =Assumptions!B43 -> 0.28 | C16: Same as income tax assumption
A17: After-Tax Cost of Debt Kd×(1−t) | B17: =B15*(1-B16) -> 0.0324 | C17: Interest tax shield applied
A19: D. CAPITAL STRUCTURE (Market Value Weights)
A20: Market Value of Equity (€ billion) | B20: =Assumptions!B45 -> 42 | C20: Preferred share price × shares + Ordinary
A21: Total Debt — Automotive Division Only (€B) | B21: =Assumptions!B46 -> 71.5 | C21: Excl. Financial Services liabilities
A22: Total Capital (E + D) | B22: =B20+B21 -> 113.5 | C22: Market Value basis
A23: Equity Weight (We = E / (E+D)) | B23: =B20/B22 -> 0.37004405 | C23: hare of equity in total capital
A24: Debt Weight (Wd = D / (E+D)) | B24: =1-B23 -> 0.62995595 | C24: Balance of capital structure
A26: E. WACC — FINAL RESULT
A27: Equity Component (We × Ke) | B27: =B23*B12 -> 0.032748899 | C27: 37.0% × 8.85%
A28: Debt Component (Wd × Kd × (1−t)) | B28: =B24*B17 -> 0.020410573 | C28: 63.0% × 3.24%
A29: ★ WACC = We×Ke + Wd×Kd×(1−t) | B29: =B27+B28 -> 0.053159471 | C29: This rate will discount FCFFs in DCF
A31: F. SANITY CHECK — REASONABLENESS TEST
A32: Industry WACC Range (Auto sector) | B32: 6% – 9%
A33: Our WACC | B33: =B29 -> 0.053159471
A34: Risk-Free Rate | B34: =B6 -> 0.028
A35: WACC > Rf? (Must be TRUE) | B35: =IF(B29>B6,"✓ YES — Logical","✗ ERROR — Check") -> ✓ YES — Logical
A36: Ke > Kd? (Must be TRUE) | B36: =IF(B12>B15,"✓ YES — Logical","✗ ERROR — Check") -> ✓ YES — Logical
A38: G. WACC SENSITIVITY — IMPACT ON VALUATION
A39: Note: WACC mein ±1% change se Enterprise Value mein ~15-20% swing aata hai. Isliye Sensitivity Analysis sheet mein WACC ko 7% se 11% range mein test karenge. Base Case WACC = 5.3% — ye conservative hai kyunki VW automotive business net cash positive hai.

Sheet DCF Valuation
A1: VOLKSWAGEN AG — DCF VALUATION (€ million)
A2: PV of FCFFs (2026E–2030E) + PV of Terminal Value = Enterprise Value → EV Bridge → Intrinsic Price
A4: DCF ITEM | B4: 2026E | C4: 2027E | D4: 2028E | E4: 2029E | F4: 2030E | G4: TOTAL / NOTES
A5: A. FREE CASH FLOW DISCOUNTING
A6: Free Cash Flow to Firm (FCFF) | B6: ='FCF Build'!C26 -> 3046.9065 | C6: ='FCF Build'!D26 -> 5996.1801 | D6: ='FCF Build'!E26 -> 8207.4066 | E6: ='FCF Build'!F26 -> 10508.04 | F6: ='FCF Build'!G26 -> 11866.654
A7: Discount Period (n) | B7: 1 | C7: 2 | D7: 3 | E7: 4 | F7: 5
A8: Discount Factor 1÷(1+WACC)^n | B8: =1/(1+WACC!B29)^B7 -> 0.94952382 | C8: =1/(1+WACC!B29)^C7 -> 0.90159548 | D8: =1/(1+WACC!B29)^D7 -> 0.85608638 | E8: =1/(1+WACC!B29)^E7 -> 0.8128744 | F8: =1/(1+WACC!B29)^F7 -> 0.77184361
A9: PV of FCFF | B9: =B6*B8 -> 2893.1103 | C9: =C6*C8 -> 5406.1289 | D9: =D6*D8 -> 7026.249 | E9: =E6*E8 -> 8541.7164 | F9: =F6*F8 -> 9159.2007 | G9: =SUM(B9:F9) -> 33026.405
A11: B. TERMINAL VALUE (Gordon Growth Model)
A12: Terminal Year FCFF (2030E) | B12: ='FCF Build'!G26 -> 11866.654
A13: Terminal Growth Rate (g) | B13: =Assumptions!B55 -> 0.02
A14: WACC (Discount Rate) | B14: =WACC!B29 -> 0.053159471
A15: Terminal Value = FCFF×(1+g) ÷ (WACC−g) | B15: =B12*(1+B13)/(B14-B13) -> 365023.51 | G15: Gordon Growth Model
A16: PV of Terminal Value | B16: =B15/(1+B14)^5 -> 281741.06
A17: Terminal Value as % of EV (sanity check) | B17: =B16/(B16+G9) -> 0.89507682
A19: C. ENTERPRISE VALUE
A20: Sum of PV of FCFFs (2026E–2030E) | B20: =G9 -> 33026.405
A21: PV of Terminal Value | B21: =B16 -> 281741.06
A22: ★ ENTERPRISE VALUE (EV) | B22: =B20+B21 -> 314767.47
A24: D. EV → EQUITY VALUE BRIDGE
A25: Enterprise Value | B25: =B22 -> 314767.47
A26: Less: Total Gross Debt (Automotive, €M) | B26: -71500
A27: Less: Pension Provisions | B27: -22826
A28: Less: Non-Controlling Interests | B28: -14777
A29: Plus: Cash & Cash Equivalents | B29: 38801
A30: Plus: Marketable Securities | B30: 29522
A31: EQUITY VALUE | B31: =SUM(B25:B30) -> 273987.47
A33: E. INTRINSIC SHARE PRICE
A34: Equity Value (€ million) | B34: =B31 -> 273987.47
A35: Total Shares Outstanding (million) | B35: 501.3
A36: Ordinary Shares (million) | B36: 295.09
A37: Preferred Shares (million) | B37: 206.21
A38: ★ INTRINSIC PRICE PER SHARE (€) | B38: =B34/B35 -> 546.5539
A40: F. VALUATION CONCLUSION
A41: Current Market Price — Preferred (€) | B41: 86.4
A42: Intrinsic Value — DCF (€) | B42: =B38 -> 546.5539
A43: Premium/(Discount) to Market | B43: =(B42-B41)/B41 -> 5.3258553
A44: Upside Potential | B44: =B42-B41 -> 460.1539
A45: VALUATION VERDICT | B45: =IF(B42>B41,"UNDERVALUED ▲","OVERVALUED ▼") -> UNDERVALUED ▲

Sheet Comps
A1: VOLKSWAGEN AG — TRADING COMPARABLES ANALYSIS (COMPS)
A2: Source: Bloomberg / FactSet estimates, June 2026. EV multiples on LTM basis. All figures in € billion unless stated.
A4: PEER GROUP — GLOBAL AUTOMOTIVE MANUFACTURERS
A5: Company | B5: Country | C5: Mkt Cap (€B) | D5: Net Debt (€B) | E5: EV (€B) | F5: Revenue (€B) | G5: EBITDA (€B) | H5: EV/EBITDA | I5: EV/Revenue | J5: P/E (NTM) | K5: P/B | L5: Note
A6: Toyota Motor Corp | B6: Japan | C6: 230 | D6: 90 | E6: 320 | F6: 275 | G6: 35 | H6: =E6/G6 -> 9.1428571 | I6: =E6/F6 -> 1.1636364 | J6: 10.5 | K6: 1.6 | L6: Largest global automaker
A7: Mercedes-Benz AG | B7: Germany | C7: 54 | D7: 31 | E7: 85 | F7: 153 | G7: 20 | H7: =E7/G7 -> 4.25 | I7: =E7/F7 -> 0.55555556 | J7: 7.2 | K7: 0.9 | L7: Premium / luxury
A8: BMW AG | B8: Germany | C8: 56 | D8: 26 | E8: 82 | F8: 142 | G8: 18 | H8: =E8/G8 -> 4.5555556 | I8: =E8/F8 -> 0.57746479 | J8: 8.1 | K8: 1 | L8: Premium, PHEV leader
A9: Stellantis NV | B9: Netherlands | C9: 38 | D9: 17 | E9: 55 | F9: 180 | G9: 22 | H9: =E9/G9 -> 2.5 | I9: =E9/F9 -> 0.30555556 | J9: 5.2 | K9: 0.7 | L9: Multi-brand volume
A10: Ford Motor Co | B10: USA | C10: 45 | D10: 35 | E10: 80 | F10: 185 | G10: 16 | H10: =E10/G10 -> 5 | I10: =E10/F10 -> 0.43243243 | J10: 8.5 | K10: 1.2 | L10: EV transition
A11: General Motors | B11: USA | C11: 43 | D11: 29 | E11: 72 | F11: 175 | G11: 18 | H11: =E11/G11 -> 4 | I11: =E11/F11 -> 0.41142857 | J11: 5 | K11: 0.9 | L11: Strong N. America
A12: Renault Group | B12: France | C12: 9 | D12: 5 | E12: 14 | F12: 47 | G12: 5 | H12: =E12/G12 -> 2.8 | I12: =E12/F12 -> 0.29787234 | J12: 4.1 | K12: 0.5 | L12: Strategic pivot
A13: Honda Motor Co | B13: Japan | C13: 44 | D13: 14 | E13: 58 | F13: 132 | G13: 14 | H13: =E13/G13 -> 4.1428571 | I13: =E13/F13 -> 0.43939394 | J13: 7.8 | K13: 0.6 | L13: Motorcycle + auto
A15: PEER STATISTICS
A16: Statistic | C16: Mkt Cap | D16: Net Debt | E16: EV | F16: Revenue | G16: EBITDA | H16: EV/EBITDA | I16: EV/Revenue | J16: P/E | K16: P/B
A17: Median | C17: =MEDIAN(C6:C13) -> 44.5 | D17: =MEDIAN(D6:D13) -> 27.5 | E17: =MEDIAN(E6:E13) -> 76 | F17: =MEDIAN(F6:F13) -> 164 | G17: =MEDIAN(G6:G13) -> 18 | H17: =MEDIAN(H6:H13) -> 4.1964286 | I17: =MEDIAN(I6:I13) -> 0.43591319 | J17: =MEDIAN(J6:J13) -> 7.5 | K17: =MEDIAN(K6:K13) -> 0.9
A18: Mean | C18: =AVERAGE(C6:C13) -> 64.875 | D18: =AVERAGE(D6:D13) -> 30.875 | E18: =AVERAGE(E6:E13) -> 95.75 | F18: =AVERAGE(F6:F13) -> 161.125 | G18: =AVERAGE(G6:G13) -> 18.5 | H18: =AVERAGE(H6:H13) -> 4.5489087 | I18: =AVERAGE(I6:I13) -> 0.52291744 | J18: =AVERAGE(J6:J13) -> 7.05 | K18: =AVERAGE(K6:K13) -> 0.925
A19: Min | C19: =MIN(C6:C13) -> 9 | D19: =MIN(D6:D13) -> 5 | E19: =MIN(E6:E13) -> 14 | F19: =MIN(F6:F13) -> 47 | G19: =MIN(G6:G13) -> 5 | H19: =MIN(H6:H13) -> 2.5 | I19: =MIN(I6:I13) -> 0.29787234 | J19: =MIN(J6:J13) -> 4.1 | K19: =MIN(K6:K13) -> 0.5
A20: Max | C20: =MAX(C6:C13) -> 230 | D20: =MAX(D6:D13) -> 90 | E20: =MAX(E6:E13) -> 320 | F20: =MAX(F6:F13) -> 275 | G20: =MAX(G6:G13) -> 35 | H20: =MAX(H6:H13) -> 9.1428571 | I20: =MAX(I6:I13) -> 1.1636364 | J20: =MAX(J6:J13) -> 10.5 | K20: =MAX(K6:K13) -> 1.6
A22: VOLKSWAGEN AG — ACTUAL DATA | B22: Country | C22: Mkt Cap (€B) | D22: Net Debt (€B) | E22: EV (€B) | F22: Revenue (€B) | G22: EBITDA (€B) | H22: EV/EBITDA | I22: EV/Revenue | J22: P/E (NTM) | K22: P/B
A23: Volkswagen AG | B23: Germany | C23: 42 | D23: 32.9 | E23: =C23+D23 -> 74.9 | F23: 321.9 | G23: 46.3 | H23: =E23/G23 -> 1.6177106 | I23: =E23/F23 -> 0.23268096 | J23: 6.3 | K23: 0.2
A25: VOLKSWAGEN IMPLIED VALUATION FROM PEER MULTIPLES
A26: Methodology | B26: Peer Median Multiple | C26: VW Metric (€B) | D26: Implied EV (€B) | E26: Implied Equity (€B) | F26: Implied Price (€)
A27: EV/EBITDA Method | B27: =H17 -> 4.1964286 | C27: =G23 -> 46.3 | D27: =B27*C27 -> 194.29464 | E27: =D27-D23+C23 -> 203.39464 | F27: =E27*1000/501.3 -> 405.73438
A28: EV/Revenue Method | B28: =I17 -> 0.43591319 | C28: =F23 -> 321.9 | D28: =B28*C28 -> 140.32045 | E28: =D28-D23+C23 -> 149.42045 | F28: =E28*1000/501.3 -> 298.06594
A29: P/E Method | B29: =J17 -> 7.5 | C29: =6.673 -> 6.673 | E29: =B29*C29 -> 50.0475 | F29: =E29*1000/501.3 -> 99.835428
A31: VALUATION SUMMARY — DCF vs COMPS
A32: Method | B32: Implied Price (€) | C32: vs Market (€86.40)
A33: DCF Base Case | B33: ='DCF Valuation'!B38 -> 546.5539 | C33: =B33-86.4 -> 460.1539
A34: EV/EBITDA Comps | B34: =F27 -> 405.73438 | C34: =B34-86.4 -> 319.33438
A35: EV/Revenue Comps | B35: =F28 -> 298.06594 | C35: =B35-86.4 -> 211.66594
A36: P/E Comps | B36: =F29 -> 99.835428 | C36: =B36-86.4 -> 13.435428
A37: Average of Methods | B37: =AVERAGE(B33:B36) -> 337.54741 | C37: =B37-86.4 -> 251.14741

Sheet Sensitivity
A1: VOLKSWAGEN AG — SENSITIVITY ANALYSIS | INTRINSIC PRICE (€/share)
A2: 2-Dimensional Table: WACC (rows) × Terminal Growth Rate (columns). Gold = Base Case cell.
A5: TABLE 1 — WACC vs TERMINAL GROWTH RATE → IMPLIED INTRINSIC PRICE (€ / Preferred Share)
A6: WACC \ TGR → | B6: 0.01 | C6: 0.015 | D6: 0.02 | E6: 0.025 | F6: 0.03 | G6: 0.035
A7: 0.04 | B7: =IFERROR(((('FCF Build'!$C$26/(1+$A7)^1)+('FCF Build'!$D$26/(1+$A7)^2)+('FCF Build'!$E$26/(1+$A7)^3)+('FCF Build'!$F$26/(1+$A7)^4)+('FCF Build'!$G$26/(1+$A7)^5))+('FCF Build'!$G$26*(1+B$6)/($A7-B$6)/(1+$A7)^5)-71500-22826-14777+38801+29522)/501.3,"N/A") -> 642.51819 | C7: =IFERROR(((('FCF Build'!$C$26/(1+$A7)^1)+('FCF Build'!$D$26/(1+$A7)^2)+('FCF Build'!$E$26/(1+$A7)^3)+('FCF Build'!$F$26/(1+$A7)^4)+('FCF Build'!$G$26/(1+$A7)^5))+('FCF Build'!$G$26*(1+C$6)/($A7-C$6)/(1+$A7)^5)-71500-22826-14777+38801+29522)/501.3,"N/A") -> 777.41632 | D7: =IFERROR(((('FCF Build'!$C$26/(1+$A7)^1)+('FCF Build'!$D$26/(1+$A7)^2)+('FCF Build'!$E$26/(1+$A7)^3)+('FCF Build'!$F$26/(1+$A7)^4)+('FCF Build'!$G$26/(1+$A7)^5))+('FCF Build'!$G$26*(1+D$6)/($A7-D$6)/(1+$A7)^5)-71500-22826-14777+38801+29522)/501.3,"N/A") -> 979.76353 | E7: =IFERROR(((('FCF Build'!$C$26/(1+$A7)^1)+('FCF Build'!$D$26/(1+$A7)^2)+('FCF Build'!$E$26/(1+$A7)^3)+('FCF Build'!$F$26/(1+$A7)^4)+('FCF Build'!$G$26/(1+$A7)^5))+('FCF Build'!$G$26*(1+E$6)/($A7-E$6)/(1+$A7)^5)-71500-22826-14777+38801+29522)/501.3,"N/A") -> 1317.0089 | F7: =IFERROR(((('FCF Build'!$C$26/(1+$A7)^1)+('FCF Build'!$D$26/(1+$A7)^2)+('FCF Build'!$E$26/(1+$A7)^3)+('FCF Build'!$F$26/(1+$A7)^4)+('FCF Build'!$G$26/(1+$A7)^5))+('FCF Build'!$G$26*(1+F$6)/($A7-F$6)/(1+$A7)^5)-71500-22826-14777+38801+29522)/501.3,"N/A") -> 1991.4995 | G7: =IFERROR(((('FCF Build'!$C$26/(1+$A7)^1)+('FCF Build'!$D$26/(1+$A7)^2)+('FCF Build'!$E$26/(1+$A7)^3)+('FCF Build'!$F$26/(1+$A7)^4)+('FCF Build'!$G$26/(1+$A7)^5))+('FCF Build'!$G$26*(1+G$6)/($A7-G$6)/(1+$A7)^5)-71500-22826-14777+38801+29522)/501.3,"N/A") -> 4014.9716
A8: 0.045 | B8: =IFERROR(((('FCF Build'!$C$26/(1+$A8)^1)+('FCF Build'!$D$26/(1+$A8)^2)+('FCF Build'!$E$26/(1+$A8)^3)+('FCF Build'!$F$26/(1+$A8)^4)+('FCF Build'!$G$26/(1+$A8)^5))+('FCF Build'!$G$26*(1+B$6)/($A8-B$6)/(1+$A8)^5)-71500-22826-14777+38801+29522)/501.3,"N/A") -> 534.49482 | C8: =IFERROR(((('FCF Build'!$C$26/(1+$A8)^1)+('FCF Build'!$D$26/(1+$A8)^2)+('FCF Build'!$E$26/(1+$A8)^3)+('FCF Build'!$F$26/(1+$A8)^4)+('FCF Build'!$G$26/(1+$A8)^5))+('FCF Build'!$G$26*(1+C$6)/($A8-C$6)/(1+$A8)^5)-71500-22826-14777+38801+29522)/501.3,"N/A") -> 629.0197 | D8: =IFERROR(((('FCF Build'!$C$26/(1+$A8)^1)+('FCF Build'!$D$26/(1+$A8)^2)+('FCF Build'!$E$26/(1+$A8)^3)+('FCF Build'!$F$26/(1+$A8)^4)+('FCF Build'!$G$26/(1+$A8)^5))+('FCF Build'!$G$26*(1+D$6)/($A8-D$6)/(1+$A8)^5)-71500-22826-14777+38801+29522)/501.3,"N/A") -> 761.35452 | E8: =IFERROR(((('FCF Build'!$C$26/(1+$A8)^1)+('FCF Build'!$D$26/(1+$A8)^2)+('FCF Build'!$E$26/(1+$A8)^3)+('FCF Build'!$F$26/(1+$A8)^4)+('FCF Build'!$G$26/(1+$A8)^5))+('FCF Build'!$G$26*(1+E$6)/($A8-E$6)/(1+$A8)^5)-71500-22826-14777+38801+29522)/501.3,"N/A") -> 959.85675 | F8: =IFERROR(((('FCF Build'!$C$26/(1+$A8)^1)+('FCF Build'!$D$26/(1+$A8)^2)+('FCF Build'!$E$26/(1+$A8)^3)+('FCF Build'!$F$26/(1+$A8)^4)+('FCF Build'!$G$26/(1+$A8)^5))+('FCF Build'!$G$26*(1+F$6)/($A8-F$6)/(1+$A8)^5)-71500-22826-14777+38801+29522)/501.3,"N/A") -> 1290.6938 | G8: =IFERROR(((('FCF Build'!$C$26/(1+$A8)^1)+('FCF Build'!$D$26/(1+$A8)^2)+('FCF Build'!$E$26/(1+$A8)^3)+('FCF Build'!$F$26/(1+$A8)^4)+('FCF Build'!$G$26/(1+$A8)^5))+('FCF Build'!$G$26*(1+G$6)/($A8-G$6)/(1+$A8)^5)-71500-22826-14777+38801+29522)/501.3,"N/A") -> 1952.3679
A9: 0.05 | B9: =IFERROR(((('FCF Build'!$C$26/(1+$A9)^1)+('FCF Build'!$D$26/(1+$A9)^2)+('FCF Build'!$E$26/(1+$A9)^3)+('FCF Build'!$F$26/(1+$A9)^4)+('FCF Build'!$G$26/(1+$A9)^5))+('FCF Build'!$G$26*(1+B$6)/($A9-B$6)/(1+$A9)^5)-71500-22826-14777+38801+29522)/501.3,"N/A") -> 453.54781 | C9: =IFERROR(((('FCF Build'!$C$26/(1+$A9)^1)+('FCF Build'!$D$26/(1+$A9)^2)+('FCF Build'!$E$26/(1+$A9)^3)+('FCF Build'!$F$26/(1+$A9)^4)+('FCF Build'!$G$26/(1+$A9)^5))+('FCF Build'!$G$26*(1+C$6)/($A9-C$6)/(1+$A9)^5)-71500-22826-14777+38801+29522)/501.3,"N/A") -> 523.10072 | D9: =IFERROR(((('FCF Build'!$C$26/(1+$A9)^1)+('FCF Build'!$D$26/(1+$A9)^2)+('FCF Build'!$E$26/(1+$A9)^3)+('FCF Build'!$F$26/(1+$A9)^4)+('FCF Build'!$G$26/(1+$A9)^5))+('FCF Build'!$G$26*(1+D$6)/($A9-D$6)/(1+$A9)^5)-71500-22826-14777+38801+29522)/501.3,"N/A") -> 615.83794 | E9: =IFERROR(((('FCF Build'!$C$26/(1+$A9)^1)+('FCF Build'!$D$26/(1+$A9)^2)+('FCF Build'!$E$26/(1+$A9)^3)+('FCF Build'!$F$26/(1+$A9)^4)+('FCF Build'!$G$26/(1+$A9)^5))+('FCF Build'!$G$26*(1+E$6)/($A9-E$6)/(1+$A9)^5)-71500-22826-14777+38801+29522)/501.3,"N/A") -> 745.67005 | F9: =IFERROR(((('FCF Build'!$C$26/(1+$A9)^1)+('FCF Build'!$D$26/(1+$A9)^2)+('FCF Build'!$E$26/(1+$A9)^3)+('FCF Build'!$F$26/(1+$A9)^4)+('FCF Build'!$G$26/(1+$A9)^5))+('FCF Build'!$G$26*(1+F$6)/($A9-F$6)/(1+$A9)^5)-71500-22826-14777+38801+29522)/501.3,"N/A") -> 940.41821 | G9: =IFERROR(((('FCF Build'!$C$26/(1+$A9)^1)+('FCF Build'!$D$26/(1+$A9)^2)+('FCF Build'!$E$26/(1+$A9)^3)+('FCF Build'!$F$26/(1+$A9)^4)+('FCF Build'!$G$26/(1+$A9)^5))+('FCF Build'!$G$26*(1+G$6)/($A9-G$6)/(1+$A9)^5)-71500-22826-14777+38801+29522)/501.3,"N/A") -> 1264.9985
A10: 0.0532 | B10: =IFERROR(((('FCF Build'!$C$26/(1+$A10)^1)+('FCF Build'!$D$26/(1+$A10)^2)+('FCF Build'!$E$26/(1+$A10)^3)+('FCF Build'!$F$26/(1+$A10)^4)+('FCF Build'!$G$26/(1+$A10)^5))+('FCF Build'!$G$26*(1+B$6)/($A10-B$6)/(1+$A10)^5)-71500-22826-14777+38801+29522)/501.3,"N/A") -> 411.60884 | C10: =IFERROR(((('FCF Build'!$C$26/(1+$A10)^1)+('FCF Build'!$D$26/(1+$A10)^2)+('FCF Build'!$E$26/(1+$A10)^3)+('FCF Build'!$F$26/(1+$A10)^4)+('FCF Build'!$G$26/(1+$A10)^5))+('FCF Build'!$G$26*(1+C$6)/($A10-C$6)/(1+$A10)^5)-71500-22826-14777+38801+29522)/501.3,"N/A") -> 469.90099 | D10: =IFERROR(((('FCF Build'!$C$26/(1+$A10)^1)+('FCF Build'!$D$26/(1+$A10)^2)+('FCF Build'!$E$26/(1+$A10)^3)+('FCF Build'!$F$26/(1+$A10)^4)+('FCF Build'!$G$26/(1+$A10)^5))+('FCF Build'!$G$26*(1+D$6)/($A10-D$6)/(1+$A10)^5)-71500-22826-14777+38801+29522)/501.3,"N/A") -> 545.75101 | E10: =IFERROR(((('FCF Build'!$C$26/(1+$A10)^1)+('FCF Build'!$D$26/(1+$A10)^2)+('FCF Build'!$E$26/(1+$A10)^3)+('FCF Build'!$F$26/(1+$A10)^4)+('FCF Build'!$G$26/(1+$A10)^5))+('FCF Build'!$G$26*(1+E$6)/($A10-E$6)/(1+$A10)^5)-71500-22826-14777+38801+29522)/501.3,"N/A") -> 648.4982 | F10: =IFERROR(((('FCF Build'!$C$26/(1+$A10)^1)+('FCF Build'!$D$26/(1+$A10)^2)+('FCF Build'!$E$26/(1+$A10)^3)+('FCF Build'!$F$26/(1+$A10)^4)+('FCF Build'!$G$26/(1+$A10)^5))+('FCF Build'!$G$26*(1+F$6)/($A10-F$6)/(1+$A10)^5)-71500-22826-14777+38801+29522)/501.3,"N/A") -> 795.53298 | G10: =IFERROR(((('FCF Build'!$C$26/(1+$A10)^1)+('FCF Build'!$D$26/(1+$A10)^2)+('FCF Build'!$E$26/(1+$A10)^3)+('FCF Build'!$F$26/(1+$A10)^4)+('FCF Build'!$G$26/(1+$A10)^5))+('FCF Build'!$G$26*(1+G$6)/($A10-G$6)/(1+$A10)^5)-71500-22826-14777+38801+29522)/501.3,"N/A") -> 1023.3561
A11: 0.06 | B11: =IFERROR(((('FCF Build'!$C$26/(1+$A11)^1)+('FCF Build'!$D$26/(1+$A11)^2)+('FCF Build'!$E$26/(1+$A11)^3)+('FCF Build'!$F$26/(1+$A11)^4)+('FCF Build'!$G$26/(1+$A11)^5))+('FCF Build'!$G$26*(1+B$6)/($A11-B$6)/(1+$A11)^5)-71500-22826-14777+38801+29522)/501.3,"N/A") -> 340.38598 | C11: =IFERROR(((('FCF Build'!$C$26/(1+$A11)^1)+('FCF Build'!$D$26/(1+$A11)^2)+('FCF Build'!$E$26/(1+$A11)^3)+('FCF Build'!$F$26/(1+$A11)^4)+('FCF Build'!$G$26/(1+$A11)^5))+('FCF Build'!$G$26*(1+C$6)/($A11-C$6)/(1+$A11)^5)-71500-22826-14777+38801+29522)/501.3,"N/A") -> 382.0532 | D11: =IFERROR(((('FCF Build'!$C$26/(1+$A11)^1)+('FCF Build'!$D$26/(1+$A11)^2)+('FCF Build'!$E$26/(1+$A11)^3)+('FCF Build'!$F$26/(1+$A11)^4)+('FCF Build'!$G$26/(1+$A11)^5))+('FCF Build'!$G$26*(1+D$6)/($A11-D$6)/(1+$A11)^5)-71500-22826-14777+38801+29522)/501.3,"N/A") -> 434.13723 | E11: =IFERROR(((('FCF Build'!$C$26/(1+$A11)^1)+('FCF Build'!$D$26/(1+$A11)^2)+('FCF Build'!$E$26/(1+$A11)^3)+('FCF Build'!$F$26/(1+$A11)^4)+('FCF Build'!$G$26/(1+$A11)^5))+('FCF Build'!$G$26*(1+E$6)/($A11-E$6)/(1+$A11)^5)-71500-22826-14777+38801+29522)/501.3,"N/A") -> 501.10242 | F11: =IFERROR(((('FCF Build'!$C$26/(1+$A11)^1)+('FCF Build'!$D$26/(1+$A11)^2)+('FCF Build'!$E$26/(1+$A11)^3)+('FCF Build'!$F$26/(1+$A11)^4)+('FCF Build'!$G$26/(1+$A11)^5))+('FCF Build'!$G$26*(1+F$6)/($A11-F$6)/(1+$A11)^5)-71500-22826-14777+38801+29522)/501.3,"N/A") -> 590.38933 | G11: =IFERROR(((('FCF Build'!$C$26/(1+$A11)^1)+('FCF Build'!$D$26/(1+$A11)^2)+('FCF Build'!$E$26/(1+$A11)^3)+('FCF Build'!$F$26/(1+$A11)^4)+('FCF Build'!$G$26/(1+$A11)^5))+('FCF Build'!$G$26*(1+G$6)/($A11-G$6)/(1+$A11)^5)-71500-22826-14777+38801+29522)/501.3,"N/A") -> 715.39101
A12: 0.07 | B12: =IFERROR(((('FCF Build'!$C$26/(1+$A12)^1)+('FCF Build'!$D$26/(1+$A12)^2)+('FCF Build'!$E$26/(1+$A12)^3)+('FCF Build'!$F$26/(1+$A12)^4)+('FCF Build'!$G$26/(1+$A12)^5))+('FCF Build'!$G$26*(1+B$6)/($A12-B$6)/(1+$A12)^5)-71500-22826-14777+38801+29522)/501.3,"N/A") -> 265.11998 | C12: =IFERROR(((('FCF Build'!$C$26/(1+$A12)^1)+('FCF Build'!$D$26/(1+$A12)^2)+('FCF Build'!$E$26/(1+$A12)^3)+('FCF Build'!$F$26/(1+$A12)^4)+('FCF Build'!$G$26/(1+$A12)^5))+('FCF Build'!$G$26*(1+C$6)/($A12-C$6)/(1+$A12)^5)-71500-22826-14777+38801+29522)/501.3,"N/A") -> 292.48221 | D12: =IFERROR(((('FCF Build'!$C$26/(1+$A12)^1)+('FCF Build'!$D$26/(1+$A12)^2)+('FCF Build'!$E$26/(1+$A12)^3)+('FCF Build'!$F$26/(1+$A12)^4)+('FCF Build'!$G$26/(1+$A12)^5))+('FCF Build'!$G$26*(1+D$6)/($A12-D$6)/(1+$A12)^5)-71500-22826-14777+38801+29522)/501.3,"N/A") -> 325.31689 | E12: =IFERROR(((('FCF Build'!$C$26/(1+$A12)^1)+('FCF Build'!$D$26/(1+$A12)^2)+('FCF Build'!$E$26/(1+$A12)^3)+('FCF Build'!$F$26/(1+$A12)^4)+('FCF Build'!$G$26/(1+$A12)^5))+('FCF Build'!$G$26*(1+E$6)/($A12-E$6)/(1+$A12)^5)-71500-22826-14777+38801+29522)/501.3,"N/A") -> 365.44817 | F12: =IFERROR(((('FCF Build'!$C$26/(1+$A12)^1)+('FCF Build'!$D$26/(1+$A12)^2)+('FCF Build'!$E$26/(1+$A12)^3)+('FCF Build'!$F$26/(1+$A12)^4)+('FCF Build'!$G$26/(1+$A12)^5))+('FCF Build'!$G$26*(1+F$6)/($A12-F$6)/(1+$A12)^5)-71500-22826-14777+38801+29522)/501.3,"N/A") -> 415.61226 | G12: =IFERROR(((('FCF Build'!$C$26/(1+$A12)^1)+('FCF Build'!$D$26/(1+$A12)^2)+('FCF Build'!$E$26/(1+$A12)^3)+('FCF Build'!$F$26/(1+$A12)^4)+('FCF Build'!$G$26/(1+$A12)^5))+('FCF Build'!$G$26*(1+G$6)/($A12-G$6)/(1+$A12)^5)-71500-22826-14777+38801+29522)/501.3,"N/A") -> 480.10895
A13: 0.08 | B13: =IFERROR(((('FCF Build'!$C$26/(1+$A13)^1)+('FCF Build'!$D$26/(1+$A13)^2)+('FCF Build'!$E$26/(1+$A13)^3)+('FCF Build'!$F$26/(1+$A13)^4)+('FCF Build'!$G$26/(1+$A13)^5))+('FCF Build'!$G$26*(1+B$6)/($A13-B$6)/(1+$A13)^5)-71500-22826-14777+38801+29522)/501.3,"N/A") -> 211.50193 | C13: =IFERROR(((('FCF Build'!$C$26/(1+$A13)^1)+('FCF Build'!$D$26/(1+$A13)^2)+('FCF Build'!$E$26/(1+$A13)^3)+('FCF Build'!$F$26/(1+$A13)^4)+('FCF Build'!$G$26/(1+$A13)^5))+('FCF Build'!$G$26*(1+C$6)/($A13-C$6)/(1+$A13)^5)-71500-22826-14777+38801+29522)/501.3,"N/A") -> 230.62221 | D13: =IFERROR(((('FCF Build'!$C$26/(1+$A13)^1)+('FCF Build'!$D$26/(1+$A13)^2)+('FCF Build'!$E$26/(1+$A13)^3)+('FCF Build'!$F$26/(1+$A13)^4)+('FCF Build'!$G$26/(1+$A13)^5))+('FCF Build'!$G$26*(1+D$6)/($A13-D$6)/(1+$A13)^5)-71500-22826-14777+38801+29522)/501.3,"N/A") -> 252.92919 | E13: =IFERROR(((('FCF Build'!$C$26/(1+$A13)^1)+('FCF Build'!$D$26/(1+$A13)^2)+('FCF Build'!$E$26/(1+$A13)^3)+('FCF Build'!$F$26/(1+$A13)^4)+('FCF Build'!$G$26/(1+$A13)^5))+('FCF Build'!$G$26*(1+E$6)/($A13-E$6)/(1+$A13)^5)-71500-22826-14777+38801+29522)/501.3,"N/A") -> 279.292 | F13: =IFERROR(((('FCF Build'!$C$26/(1+$A13)^1)+('FCF Build'!$D$26/(1+$A13)^2)+('FCF Build'!$E$26/(1+$A13)^3)+('FCF Build'!$F$26/(1+$A13)^4)+('FCF Build'!$G$26/(1+$A13)^5))+('FCF Build'!$G$26*(1+F$6)/($A13-F$6)/(1+$A13)^5)-71500-22826-14777+38801+29522)/501.3,"N/A") -> 310.92736 | G13: =IFERROR(((('FCF Build'!$C$26/(1+$A13)^1)+('FCF Build'!$D$26/(1+$A13)^2)+('FCF Build'!$E$26/(1+$A13)^3)+('FCF Build'!$F$26/(1+$A13)^4)+('FCF Build'!$G$26/(1+$A13)^5))+('FCF Build'!$G$26*(1+G$6)/($A13-G$6)/(1+$A13)^5)-71500-22826-14777+38801+29522)/501.3,"N/A") -> 349.59281
A14: 0.09 | B14: =IFERROR(((('FCF Build'!$C$26/(1+$A14)^1)+('FCF Build'!$D$26/(1+$A14)^2)+('FCF Build'!$E$26/(1+$A14)^3)+('FCF Build'!$F$26/(1+$A14)^4)+('FCF Build'!$G$26/(1+$A14)^5))+('FCF Build'!$G$26*(1+B$6)/($A14-B$6)/(1+$A14)^5)-71500-22826-14777+38801+29522)/501.3,"N/A") -> 171.40821 | C14: =IFERROR(((('FCF Build'!$C$26/(1+$A14)^1)+('FCF Build'!$D$26/(1+$A14)^2)+('FCF Build'!$E$26/(1+$A14)^3)+('FCF Build'!$F$26/(1+$A14)^4)+('FCF Build'!$G$26/(1+$A14)^5))+('FCF Build'!$G$26*(1+C$6)/($A14-C$6)/(1+$A14)^5)-71500-22826-14777+38801+29522)/501.3,"N/A") -> 185.38293 | D14: =IFERROR(((('FCF Build'!$C$26/(1+$A14)^1)+('FCF Build'!$D$26/(1+$A14)^2)+('FCF Build'!$E$26/(1+$A14)^3)+('FCF Build'!$F$26/(1+$A14)^4)+('FCF Build'!$G$26/(1+$A14)^5))+('FCF Build'!$G$26*(1+D$6)/($A14-D$6)/(1+$A14)^5)-71500-22826-14777+38801+29522)/501.3,"N/A") -> 201.35405 | E14: =IFERROR(((('FCF Build'!$C$26/(1+$A14)^1)+('FCF Build'!$D$26/(1+$A14)^2)+('FCF Build'!$E$26/(1+$A14)^3)+('FCF Build'!$F$26/(1+$A14)^4)+('FCF Build'!$G$26/(1+$A14)^5))+('FCF Build'!$G$26*(1+E$6)/($A14-E$6)/(1+$A14)^5)-71500-22826-14777+38801+29522)/501.3,"N/A") -> 219.78226 | F14: =IFERROR(((('FCF Build'!$C$26/(1+$A14)^1)+('FCF Build'!$D$26/(1+$A14)^2)+('FCF Build'!$E$26/(1+$A14)^3)+('FCF Build'!$F$26/(1+$A14)^4)+('FCF Build'!$G$26/(1+$A14)^5))+('FCF Build'!$G$26*(1+F$6)/($A14-F$6)/(1+$A14)^5)-71500-22826-14777+38801+29522)/501.3,"N/A") -> 241.28184 | G14: =IFERROR(((('FCF Build'!$C$26/(1+$A14)^1)+('FCF Build'!$D$26/(1+$A14)^2)+('FCF Build'!$E$26/(1+$A14)^3)+('FCF Build'!$F$26/(1+$A14)^4)+('FCF Build'!$G$26/(1+$A14)^5))+('FCF Build'!$G$26*(1+G$6)/($A14-G$6)/(1+$A14)^5)-71500-22826-14777+38801+29522)/501.3,"N/A") -> 266.69043
A16: Current Market Price (€) | B16: 86.4 | C16: ← Reference: At which WACC/TGR does intrinsic = market price?
A18: TABLE 2 — EBIT MARGIN vs REVENUE GROWTH → IMPLIED INTRINSIC PRICE (€/share)
A19: EBIT/REVENUE | B19: 0 | C19: 0.015 | D19: 0.025 | E19: 0.035 | F19: 0.05
A20: 0.03 | B20: =IFERROR((321913*($A20*0.72+0.064-0.076)*((1+B$19)/(1+WACC!$B$29)+(1+B$19)^2/(1+WACC!$B$29)^2+(1+B$19)^3/(1+WACC!$B$29)^3+(1+B$19)^4/(1+WACC!$B$29)^4+(1+B$19)^5/(1+WACC!$B$29)^5)+321913*(1+B$19)^5*($A20*0.72+0.064-0.076)*1.02/(WACC!$B$29-0.02)/(1+WACC!$B$29)^5-71500-22826-14777+38801+29522)/501.3,"N/A") -> 91.473819 | C20: =IFERROR((321913*($A20*0.72+0.064-0.076)*((1+C$19)/(1+WACC!$B$29)+(1+C$19)^2/(1+WACC!$B$29)^2+(1+C$19)^3/(1+WACC!$B$29)^3+(1+C$19)^4/(1+WACC!$B$29)^4+(1+C$19)^5/(1+WACC!$B$29)^5)+321913*(1+C$19)^5*($A20*0.72+0.064-0.076)*1.02/(WACC!$B$29-0.02)/(1+WACC!$B$29)^5-71500-22826-14777+38801+29522)/501.3,"N/A") -> 103.9575 | D20: =IFERROR((321913*($A20*0.72+0.064-0.076)*((1+D$19)/(1+WACC!$B$29)+(1+D$19)^2/(1+WACC!$B$29)^2+(1+D$19)^3/(1+WACC!$B$29)^3+(1+D$19)^4/(1+WACC!$B$29)^4+(1+D$19)^5/(1+WACC!$B$29)^5)+321913*(1+D$19)^5*($A20*0.72+0.064-0.076)*1.02/(WACC!$B$29-0.02)/(1+WACC!$B$29)^5-71500-22826-14777+38801+29522)/501.3,"N/A") -> 112.68623 | E20: =IFERROR((321913*($A20*0.72+0.064-0.076)*((1+E$19)/(1+WACC!$B$29)+(1+E$19)^2/(1+WACC!$B$29)^2+(1+E$19)^3/(1+WACC!$B$29)^3+(1+E$19)^4/(1+WACC!$B$29)^4+(1+E$19)^5/(1+WACC!$B$29)^5)+321913*(1+E$19)^5*($A20*0.72+0.064-0.076)*1.02/(WACC!$B$29-0.02)/(1+WACC!$B$29)^5-71500-22826-14777+38801+29522)/501.3,"N/A") -> 121.75113 | F20: =IFERROR((321913*($A20*0.72+0.064-0.076)*((1+F$19)/(1+WACC!$B$29)+(1+F$19)^2/(1+WACC!$B$29)^2+(1+F$19)^3/(1+WACC!$B$29)^3+(1+F$19)^4/(1+WACC!$B$29)^4+(1+F$19)^5/(1+WACC!$B$29)^5)+321913*(1+F$19)^5*($A20*0.72+0.064-0.076)*1.02/(WACC!$B$29-0.02)/(1+WACC!$B$29)^5-71500-22826-14777+38801+29522)/501.3,"N/A") -> 136.00024
A21: 0.04 | B21: =IFERROR((321913*($A21*0.72+0.064-0.076)*((1+B$19)/(1+WACC!$B$29)+(1+B$19)^2/(1+WACC!$B$29)^2+(1+B$19)^3/(1+WACC!$B$29)^3+(1+B$19)^4/(1+WACC!$B$29)^4+(1+B$19)^5/(1+WACC!$B$29)^5)+321913*(1+B$19)^5*($A21*0.72+0.064-0.076)*1.02/(WACC!$B$29-0.02)/(1+WACC!$B$29)^5-71500-22826-14777+38801+29522)/501.3,"N/A") -> 221.09055 | C21: =IFERROR((321913*($A21*0.72+0.064-0.076)*((1+C$19)/(1+WACC!$B$29)+(1+C$19)^2/(1+WACC!$B$29)^2+(1+C$19)^3/(1+WACC!$B$29)^3+(1+C$19)^4/(1+WACC!$B$29)^4+(1+C$19)^5/(1+WACC!$B$29)^5)+321913*(1+C$19)^5*($A21*0.72+0.064-0.076)*1.02/(WACC!$B$29-0.02)/(1+WACC!$B$29)^5-71500-22826-14777+38801+29522)/501.3,"N/A") -> 242.937 | D21: =IFERROR((321913*($A21*0.72+0.064-0.076)*((1+D$19)/(1+WACC!$B$29)+(1+D$19)^2/(1+WACC!$B$29)^2+(1+D$19)^3/(1+WACC!$B$29)^3+(1+D$19)^4/(1+WACC!$B$29)^4+(1+D$19)^5/(1+WACC!$B$29)^5)+321913*(1+D$19)^5*($A21*0.72+0.064-0.076)*1.02/(WACC!$B$29-0.02)/(1+WACC!$B$29)^5-71500-22826-14777+38801+29522)/501.3,"N/A") -> 258.21227 | E21: =IFERROR((321913*($A21*0.72+0.064-0.076)*((1+E$19)/(1+WACC!$B$29)+(1+E$19)^2/(1+WACC!$B$29)^2+(1+E$19)^3/(1+WACC!$B$29)^3+(1+E$19)^4/(1+WACC!$B$29)^4+(1+E$19)^5/(1+WACC!$B$29)^5)+321913*(1+E$19)^5*($A21*0.72+0.064-0.076)*1.02/(WACC!$B$29-0.02)/(1+WACC!$B$29)^5-71500-22826-14777+38801+29522)/501.3,"N/A") -> 274.07584 | F21: =IFERROR((321913*($A21*0.72+0.064-0.076)*((1+F$19)/(1+WACC!$B$29)+(1+F$19)^2/(1+WACC!$B$29)^2+(1+F$19)^3/(1+WACC!$B$29)^3+(1+F$19)^4/(1+WACC!$B$29)^4+(1+F$19)^5/(1+WACC!$B$29)^5)+321913*(1+F$19)^5*($A21*0.72+0.064-0.076)*1.02/(WACC!$B$29-0.02)/(1+WACC!$B$29)^5-71500-22826-14777+38801+29522)/501.3,"N/A") -> 299.01178
A22: 0.05 | B22: =IFERROR((321913*($A22*0.72+0.064-0.076)*((1+B$19)/(1+WACC!$B$29)+(1+B$19)^2/(1+WACC!$B$29)^2+(1+B$19)^3/(1+WACC!$B$29)^3+(1+B$19)^4/(1+WACC!$B$29)^4+(1+B$19)^5/(1+WACC!$B$29)^5)+321913*(1+B$19)^5*($A22*0.72+0.064-0.076)*1.02/(WACC!$B$29-0.02)/(1+WACC!$B$29)^5-71500-22826-14777+38801+29522)/501.3,"N/A") -> 350.70729 | C22: =IFERROR((321913*($A22*0.72+0.064-0.076)*((1+C$19)/(1+WACC!$B$29)+(1+C$19)^2/(1+WACC!$B$29)^2+(1+C$19)^3/(1+WACC!$B$29)^3+(1+C$19)^4/(1+WACC!$B$29)^4+(1+C$19)^5/(1+WACC!$B$29)^5)+321913*(1+C$19)^5*($A22*0.72+0.064-0.076)*1.02/(WACC!$B$29-0.02)/(1+WACC!$B$29)^5-71500-22826-14777+38801+29522)/501.3,"N/A") -> 381.9165 | D22: =IFERROR((321913*($A22*0.72+0.064-0.076)*((1+D$19)/(1+WACC!$B$29)+(1+D$19)^2/(1+WACC!$B$29)^2+(1+D$19)^3/(1+WACC!$B$29)^3+(1+D$19)^4/(1+WACC!$B$29)^4+(1+D$19)^5/(1+WACC!$B$29)^5)+321913*(1+D$19)^5*($A22*0.72+0.064-0.076)*1.02/(WACC!$B$29-0.02)/(1+WACC!$B$29)^5-71500-22826-14777+38801+29522)/501.3,"N/A") -> 403.73831 | E22: =IFERROR((321913*($A22*0.72+0.064-0.076)*((1+E$19)/(1+WACC!$B$29)+(1+E$19)^2/(1+WACC!$B$29)^2+(1+E$19)^3/(1+WACC!$B$29)^3+(1+E$19)^4/(1+WACC!$B$29)^4+(1+E$19)^5/(1+WACC!$B$29)^5)+321913*(1+E$19)^5*($A22*0.72+0.064-0.076)*1.02/(WACC!$B$29-0.02)/(1+WACC!$B$29)^5-71500-22826-14777+38801+29522)/501.3,"N/A") -> 426.40056 | F22: =IFERROR((321913*($A22*0.72+0.064-0.076)*((1+F$19)/(1+WACC!$B$29)+(1+F$19)^2/(1+WACC!$B$29)^2+(1+F$19)^3/(1+WACC!$B$29)^3+(1+F$19)^4/(1+WACC!$B$29)^4+(1+F$19)^5/(1+WACC!$B$29)^5)+321913*(1+F$19)^5*($A22*0.72+0.064-0.076)*1.02/(WACC!$B$29-0.02)/(1+WACC!$B$29)^5-71500-22826-14777+38801+29522)/501.3,"N/A") -> 462.02333
A23: 0.06 | B23: =IFERROR((321913*($A23*0.72+0.064-0.076)*((1+B$19)/(1+WACC!$B$29)+(1+B$19)^2/(1+WACC!$B$29)^2+(1+B$19)^3/(1+WACC!$B$29)^3+(1+B$19)^4/(1+WACC!$B$29)^4+(1+B$19)^5/(1+WACC!$B$29)^5)+321913*(1+B$19)^5*($A23*0.72+0.064-0.076)*1.02/(WACC!$B$29-0.02)/(1+WACC!$B$29)^5-71500-22826-14777+38801+29522)/501.3,"N/A") -> 480.32402 | C23: =IFERROR((321913*($A23*0.72+0.064-0.076)*((1+C$19)/(1+WACC!$B$29)+(1+C$19)^2/(1+WACC!$B$29)^2+(1+C$19)^3/(1+WACC!$B$29)^3+(1+C$19)^4/(1+WACC!$B$29)^4+(1+C$19)^5/(1+WACC!$B$29)^5)+321913*(1+C$19)^5*($A23*0.72+0.064-0.076)*1.02/(WACC!$B$29-0.02)/(1+WACC!$B$29)^5-71500-22826-14777+38801+29522)/501.3,"N/A") -> 520.89599 | D23: =IFERROR((321913*($A23*0.72+0.064-0.076)*((1+D$19)/(1+WACC!$B$29)+(1+D$19)^2/(1+WACC!$B$29)^2+(1+D$19)^3/(1+WACC!$B$29)^3+(1+D$19)^4/(1+WACC!$B$29)^4+(1+D$19)^5/(1+WACC!$B$29)^5)+321913*(1+D$19)^5*($A23*0.72+0.064-0.076)*1.02/(WACC!$B$29-0.02)/(1+WACC!$B$29)^5-71500-22826-14777+38801+29522)/501.3,"N/A") -> 549.26435 | E23: =IFERROR((321913*($A23*0.72+0.064-0.076)*((1+E$19)/(1+WACC!$B$29)+(1+E$19)^2/(1+WACC!$B$29)^2+(1+E$19)^3/(1+WACC!$B$29)^3+(1+E$19)^4/(1+WACC!$B$29)^4+(1+E$19)^5/(1+WACC!$B$29)^5)+321913*(1+E$19)^5*($A23*0.72+0.064-0.076)*1.02/(WACC!$B$29-0.02)/(1+WACC!$B$29)^5-71500-22826-14777+38801+29522)/501.3,"N/A") -> 578.72527 | F23: =IFERROR((321913*($A23*0.72+0.064-0.076)*((1+F$19)/(1+WACC!$B$29)+(1+F$19)^2/(1+WACC!$B$29)^2+(1+F$19)^3/(1+WACC!$B$29)^3+(1+F$19)^4/(1+WACC!$B$29)^4+(1+F$19)^5/(1+WACC!$B$29)^5)+321913*(1+F$19)^5*($A23*0.72+0.064-0.076)*1.02/(WACC!$B$29-0.02)/(1+WACC!$B$29)^5-71500-22826-14777+38801+29522)/501.3,"N/A") -> 625.03488
A24: 0.07 | B24: =IFERROR((321913*($A24*0.72+0.064-0.076)*((1+B$19)/(1+WACC!$B$29)+(1+B$19)^2/(1+WACC!$B$29)^2+(1+B$19)^3/(1+WACC!$B$29)^3+(1+B$19)^4/(1+WACC!$B$29)^4+(1+B$19)^5/(1+WACC!$B$29)^5)+321913*(1+B$19)^5*($A24*0.72+0.064-0.076)*1.02/(WACC!$B$29-0.02)/(1+WACC!$B$29)^5-71500-22826-14777+38801+29522)/501.3,"N/A") -> 609.94076 | C24: =IFERROR((321913*($A24*0.72+0.064-0.076)*((1+C$19)/(1+WACC!$B$29)+(1+C$19)^2/(1+WACC!$B$29)^2+(1+C$19)^3/(1+WACC!$B$29)^3+(1+C$19)^4/(1+WACC!$B$29)^4+(1+C$19)^5/(1+WACC!$B$29)^5)+321913*(1+C$19)^5*($A24*0.72+0.064-0.076)*1.02/(WACC!$B$29-0.02)/(1+WACC!$B$29)^5-71500-22826-14777+38801+29522)/501.3,"N/A") -> 659.87549 | D24: =IFERROR((321913*($A24*0.72+0.064-0.076)*((1+D$19)/(1+WACC!$B$29)+(1+D$19)^2/(1+WACC!$B$29)^2+(1+D$19)^3/(1+WACC!$B$29)^3+(1+D$19)^4/(1+WACC!$B$29)^4+(1+D$19)^5/(1+WACC!$B$29)^5)+321913*(1+D$19)^5*($A24*0.72+0.064-0.076)*1.02/(WACC!$B$29-0.02)/(1+WACC!$B$29)^5-71500-22826-14777+38801+29522)/501.3,"N/A") -> 694.79039 | E24: =IFERROR((321913*($A24*0.72+0.064-0.076)*((1+E$19)/(1+WACC!$B$29)+(1+E$19)^2/(1+WACC!$B$29)^2+(1+E$19)^3/(1+WACC!$B$29)^3+(1+E$19)^4/(1+WACC!$B$29)^4+(1+E$19)^5/(1+WACC!$B$29)^5)+321913*(1+E$19)^5*($A24*0.72+0.064-0.076)*1.02/(WACC!$B$29-0.02)/(1+WACC!$B$29)^5-71500-22826-14777+38801+29522)/501.3,"N/A") -> 731.04998 | F24: =IFERROR((321913*($A24*0.72+0.064-0.076)*((1+F$19)/(1+WACC!$B$29)+(1+F$19)^2/(1+WACC!$B$29)^2+(1+F$19)^3/(1+WACC!$B$29)^3+(1+F$19)^4/(1+WACC!$B$29)^4+(1+F$19)^5/(1+WACC!$B$29)^5)+321913*(1+F$19)^5*($A24*0.72+0.064-0.076)*1.02/(WACC!$B$29-0.02)/(1+WACC!$B$29)^5-71500-22826-14777+38801+29522)/501.3,"N/A") -> 788.04643
A26: INTERPRETATION GUIDE
A27: Gold cell = Base Case (WACC 5.32%, TGR 2.0%) → €546/share
A28: Green cells = Higher intrinsic value (undervalued zone)
A29: Red cells = Lower intrinsic value (closer to market price)
A30: At WACC ~8-9% with TGR ~1.5%, price approaches market range (€100-150)
A31: Key Insight: Results highly sensitive to WACC — small change = big impact

Sheet Football Field
A1: VOLKSWAGEN AG — FOOTBALL FIELD VALUATION SUMMARY
A2: Valuation range across methodologies. Current market price = reference. All prices in €/share.
A4: VALUATION RANGE TABLE (€/share)
A5: Methodology | B5: Low (€) | C5: Mid-Point (€) | D5: High (€) | E5: Current Price (€)
A6: DCF — Base Case | B6: 350 | C6: ='DCF Valuation'!B38 -> 546.5539 | D6: 750 | E6: 86.4
A7: DCF — Bull Case | B7: 500 | C7: 800 | D7: 1100 | E7: 86.4
A8: DCF — Bear Case | B8: 150 | C8: 250 | D8: 400 | E8: 86.4
A9: EV/EBITDA Comps | B9: 280 | C9: =Comps!F27 -> 405.73438 | D9: 550 | E9: 86.4
A10: EV/Revenue Comps | B10: 150 | C10: =Comps!F28 -> 298.06594 | D10: 400 | E10: 86.4
A11: P/E Comps | B11: 60 | C11: =Comps!F29 -> 99.835428 | D11: 160 | E11: 86.4
A12: 52-Week Trading Range | B12: 79.2 | C12: 92 | D12: 115.85 | E12: 86.4
A14: KEY TAKEAWAYS
A15: ★ All valuation methods except 52-week range indicate UNDERVALUATION
A16: ★ DCF Base Case: €546.55 — 6.3x market price
A17: ★ EV/EBITDA Comps: €405.73 — 4.7x market price
A18: ★ Even bear case DCF (€250) is 2.9x current price
A19: ★ Only P/E method (€99.84) is close to market — depressed earnings effect
A20: ★ Verdict: VW appears significantly UNDERVALUED on fundamental basis

Sheet KPI Dashboard
A1: VOLKSWAGEN AG — EXECUTIVE KPI DASHBOARD
A2: Key performance indicators — Historical (2021–2025) | Forecast (2026E–2030E) | Valuation Summary
